<?xml version="1.0" ?>
<!-- =================================================================================== -->
<!-- |    This document was autogenerated by xacro from waco.urdf.xacro                | -->
<!-- |    EDITING THIS FILE BY HAND IS NOT RECOMMENDED                                 | -->
<!-- =================================================================================== -->
<robot name="waco" xmlns:body="http://playerstage.sourceforge.net/gazebo/xmlschema/#body" xmlns:controller="http://playerstage.sourceforge.net/gazebo/xmlschema/#controller" xmlns:gazebo="http://playerstage.sourceforge.net/gazebo/xmlschema/#gz" xmlns:geom="http://playerstage.sourceforge.net/gazebo/xmlschema/#geom" xmlns:interface="http://playerstage.sourceforge.net/gazebo/xmlschema/#interface" xmlns:joint="http://playerstage.sourceforge.net/gazebo/xmlschema/#joint" xmlns:model="http://playerstage.sourceforge.net/gazebo/xmlschema/#model" xmlns:physics="http://playerstage.sourceforge.net/gazebo/xmlschema/#physics" xmlns:renderable="http://playerstage.sourceforge.net/gazebo/xmlschema/#renderable" xmlns:rendering="http://playerstage.sourceforge.net/gazebo/xmlschema/#rendering" xmlns:sensor="http://playerstage.sourceforge.net/gazebo/xmlschema/#sensor" xmlns:xacro="http://www.ros.org/wiki/xacro" xmlns:xi="http://www.w3.org/2001/XInclude">
  <!-- Materials -->
  <material name="black">
    <color rgba="0 0 0 255"/>
  </material>
  <material name="blue">
    <color rgba="0 0 200 255"/>
  </material>
  <material name="green">
    <color rgba="0 200 0 255"/>
  </material>
  <material name="grey">
    <color rgba="50 50 50 255"/>
  </material>
  <material name="orange">
    <color rgba="255 108 10 255"/>
  </material>
  <material name="brown">
    <color rgba="222 207 195 255"/>
  </material>
  <material name="red">
    <color rgba="200 0 0 255"/>
  </material>
  <material name="white">
    <color rgba="255 255 255 255"/>
  </material>
  <!-- links      		mesh_no
   base           		0
   shoulder       		1
   arm            		2
   forearm        		3
   wrist          		4
   arm_mico       		5
   arm_half1 (7dof)		6
   arm_half2 (7dof)		7
   wrist_spherical_1  8
   wrist_spherical_2  9

   hand 3 finger  		55
   hand_2finger   		56
   finger_proximal		57
   finger_distal      58 
-->
  <!-- links      		mesh_no
   base           		0
   shoulder       		1
   arm            		2
   forearm        		3
   wrist          		4
   arm_mico       		5
   arm_half1 (7dof)		6
   arm_half2 (7dof)		7
   wrist_spherical_1  8
   wrist_spherical_2  9

   hand 3 finger  		55
   hand_2finger   		56
   finger_proximal		57
   finger_distal      58 
-->
  <!-- Import all Gazebo-customization elements -->
  <!--xacro:include filename="$(find kinova_description)/urdf/kinova.gazebo" /-->
  <link name="base"/>
  <joint name="base_joint" type="fixed">
    <parent link="base"/>
    <child link="smb_chassis"/>
  </joint>
  <link name="smb_chassis">
    <collision>
      <origin rpy="0 0 0" xyz="0 0 0.19"/>
      <geometry>
        <box size="0.6 0.41 0.22"/>
      </geometry>
    </collision>
    <visual>
      <origin rpy="0 0 0" xyz="0 0 0.19"/>
      <geometry>
        <box size="0.6 0.41 0.22"/>
      </geometry>
      <material name="green"/>
    </visual>
    <inertial>
      <origin rpy="0 0 0" xyz="0 0 0.19"/>
      <mass value="110"/>
      <inertia ixx="1.98458333333" ixy="0" ixz="0" iyy="3.74366666667" iyz="0" izz="3.74366666667"/>
    </inertial>
  </link>
  <gazebo reference="smb_chassis">
    <material>Gazebo/Green</material>
  </gazebo>
  <joint name="smb_wheel_fl_hinge" type="continuous">
    <parent link="smb_chassis"/>
    <child link="smb_wheel_fl"/>
    <origin rpy="0 0 0" xyz="0.2159 0.265 0.14"/>
    <axis rpy="0 0 0" xyz="0 1 0"/>
    <dynamics damping="1.0" friction="0.0"/>
    <limit effort="1" velocity="1"/>
    <joint_properties damping="0.2" friction="0.2"/>
  </joint>
  <link name="smb_wheel_fl">
    <collision>
      <origin rpy="1.57079632679 0 0" xyz="0 0 0"/>
      <geometry>
        <cylinder length="0.08" radius="0.14"/>
      </geometry>
    </collision>
    <visual>
      <origin rpy="1.57079632679 0 0" xyz="0 0 0"/>
      <geometry>
        <cylinder length="0.08" radius="0.14"/>
      </geometry>
      <material name="black"/>
    </visual>
    <inertial>
      <origin rpy="1.57079632679 0 0" xyz="0 0 0"/>
      <mass value="5"/>
      <inertia ixx="0.0271666666667" ixy="0" ixz="0" iyy="0.0271666666667" iyz="0" izz="0.049"/>
    </inertial>
  </link>
  <gazebo reference="smb_wheel_fl">
    <mu1 value="0.2"/>
    <mu2 value="0.2"/>
    <fdir1 value="1 0 0"/>
    <kp>10000000.0</kp>
    <kd>1.0</kd>
    <minDepth>0.005</minDepth>
    <maxVel>100.0</maxVel>
    <material>Gazebo/Black</material>
  </gazebo>
  <joint name="smb_wheel_fr_hinge" type="continuous">
    <parent link="smb_chassis"/>
    <child link="smb_wheel_fr"/>
    <origin rpy="0 0 0" xyz="0.2159 -0.265 0.14"/>
    <axis rpy="0 0 0" xyz="0 1 0"/>
    <dynamics damping="1.0" friction="0.0"/>
    <limit effort="1" velocity="1"/>
    <joint_properties damping="0.2" friction="0.2"/>
  </joint>
  <link name="smb_wheel_fr">
    <collision>
      <origin rpy="1.57079632679 0 0" xyz="0 0 0"/>
      <geometry>
        <cylinder length="0.08" radius="0.14"/>
      </geometry>
    </collision>
    <visual>
      <origin rpy="1.57079632679 0 0" xyz="0 0 0"/>
      <geometry>
        <cylinder length="0.08" radius="0.14"/>
      </geometry>
      <material name="black"/>
    </visual>
    <inertial>
      <origin rpy="1.57079632679 0 0" xyz="0 0 0"/>
      <mass value="5"/>
      <inertia ixx="0.0271666666667" ixy="0" ixz="0" iyy="0.0271666666667" iyz="0" izz="0.049"/>
    </inertial>
  </link>
  <gazebo reference="smb_wheel_fr">
    <mu1 value="0.2"/>
    <mu2 value="0.2"/>
    <fdir1 value="1 0 0"/>
    <kp>10000000.0</kp>
    <kd>1.0</kd>
    <minDepth>0.005</minDepth>
    <maxVel>100.0</maxVel>
    <material>Gazebo/Black</material>
  </gazebo>
  <joint name="smb_wheel_bl_hinge" type="continuous">
    <parent link="smb_chassis"/>
    <child link="smb_wheel_bl"/>
    <origin rpy="0 0 0" xyz="-0.2159 0.265 0.14"/>
    <axis rpy="0 0 0" xyz="0 1 0"/>
    <dynamics damping="1.0" friction="0.0"/>
    <limit effort="1" velocity="1"/>
    <joint_properties damping="0.2" friction="0.2"/>
  </joint>
  <link name="smb_wheel_bl">
    <collision>
      <origin rpy="1.57079632679 0 0" xyz="0 0 0"/>
      <geometry>
        <cylinder length="0.08" radius="0.14"/>
      </geometry>
    </collision>
    <visual>
      <origin rpy="1.57079632679 0 0" xyz="0 0 0"/>
      <geometry>
        <cylinder length="0.08" radius="0.14"/>
      </geometry>
      <material name="black"/>
    </visual>
    <inertial>
      <origin rpy="1.57079632679 0 0" xyz="0 0 0"/>
      <mass value="5"/>
      <inertia ixx="0.0271666666667" ixy="0" ixz="0" iyy="0.0271666666667" iyz="0" izz="0.049"/>
    </inertial>
  </link>
  <gazebo reference="smb_wheel_bl">
    <mu1 value="0.2"/>
    <mu2 value="0.2"/>
    <fdir1 value="1 0 0"/>
    <kp>10000000.0</kp>
    <kd>1.0</kd>
    <minDepth>0.005</minDepth>
    <maxVel>100.0</maxVel>
    <material>Gazebo/Black</material>
  </gazebo>
  <joint name="smb_wheel_br_hinge" type="continuous">
    <parent link="smb_chassis"/>
    <child link="smb_wheel_br"/>
    <origin rpy="0 0 0" xyz="-0.2159 -0.265 0.14"/>
    <axis rpy="0 0 0" xyz="0 1 0"/>
    <dynamics damping="1.0" friction="0.0"/>
    <limit effort="1" velocity="1"/>
    <joint_properties damping="0.2" friction="0.2"/>
  </joint>
  <link name="smb_wheel_br">
    <collision>
      <origin rpy="1.57079632679 0 0" xyz="0 0 0"/>
      <geometry>
        <cylinder length="0.08" radius="0.14"/>
      </geometry>
    </collision>
    <visual>
      <origin rpy="1.57079632679 0 0" xyz="0 0 0"/>
      <geometry>
        <cylinder length="0.08" radius="0.14"/>
      </geometry>
      <material name="black"/>
    </visual>
    <inertial>
      <origin rpy="1.57079632679 0 0" xyz="0 0 0"/>
      <mass value="5"/>
      <inertia ixx="0.0271666666667" ixy="0" ixz="0" iyy="0.0271666666667" iyz="0" izz="0.049"/>
    </inertial>
  </link>
  <gazebo reference="smb_wheel_br">
    <mu1 value="0.2"/>
    <mu2 value="0.2"/>
    <fdir1 value="1 0 0"/>
    <kp>10000000.0</kp>
    <kd>1.0</kd>
    <minDepth>0.005</minDepth>
    <maxVel>100.0</maxVel>
    <material>Gazebo/Black</material>
  </gazebo>
  <link name="arm_base">  </link>
  <joint name="base_to_arm_base" type="fixed">
    <child link="arm_base"/>
    <parent link="base"/>
    <origin rpy="0 0 1.57079632679" xyz="0.1 0.0 0.27"/>
  </joint>
  <!--xacro:gazebo_config robot_namespace="${prefix}"/-->
  <link name="kinova_link_base">
    <visual>
      <geometry>
        <mesh filename="package://kinova_description/meshes/base.dae"/>
      </geometry>
      <material name="carbon_fiber">
        <color rgba="0.792156862745098 0.819607843137255 0.933333333333333 1"/>
      </material>
    </visual>
    <collision>
      <geometry>
        <mesh filename="package://kinova_description/meshes/base.dae"/>
      </geometry>
    </collision>
    <!-- <xacro:kinova_inertial mesh_no="${mesh_no}"/>   -->
  </link>
  <!-- Fixed joint to add dummy inertia link -->
  <joint name="kinova_link_base_to_kinova_link_base_inertia" type="fixed">
    <parent link="kinova_link_base"/>
    <child link="kinova_link_base_inertia"/>
    <origin rpy="0 0 0" xyz="0 0 0"/>
  </joint>
  <!-- Dummy inertia link, because KDL cannot have inertia on the base link -->
  <link name="kinova_link_base_inertia">
    <inertial>
      <mass value="0.46784"/>
      <origin rpy="0 0 0" xyz="0 0 0.1255"/>
      <inertia ixx="0.000951270861568" ixy="0" ixz="0" iyy="0.000951270861568" iyz="0" izz="0.000374272"/>
    </inertial>
  </link>
  <joint name="kinova_joint_base" type="fixed">
    <parent link="arm_base"/>
    <child link="kinova_link_base"/>
    <axis xyz="0 0 0"/>
    <limit effort="1000" lower="0" upper="0" velocity="15"/>
    <!-- limit effort also defines torque limit and freeze controller gains -->
    <origin rpy="0 0 0" xyz="0 0 0"/>
    <dynamics damping="0.0" friction="0.0"/>
  </joint>
  <!--
   <xacro:unless value="${fixed}">
     <transmission name="${joint_name}_trans">
        <type>transmission_interface/SimpleTransmission</type>
        <joint name="${joint_name}">
          <hardwareInterface>EffortJointInterface</hardwareInterface>
        </joint>
        <actuator name="${joint_name}_actuator">
          <hardwareInterface>EffortJointInterface</hardwareInterface>
        <mechanicalReduction>160</mechanicalReduction>
        </actuator>
     </transmission>
     </xacro:unless>
-->
  <link name="kinova_link_1">
    <visual>
      <geometry>
        <mesh filename="package://kinova_description/meshes/shoulder.dae"/>
      </geometry>
      <material name="carbon_fiber">
        <color rgba="0.792156862745098 0.819607843137255 0.933333333333333 1"/>
      </material>
    </visual>
    <visual>
      <geometry>
        <mesh filename="package://kinova_description/meshes/ring_big.STL"/>
      </geometry>
    </visual>
    <collision>
      <geometry>
        <mesh filename="package://kinova_description/meshes/shoulder.dae"/>
      </geometry>
    </collision>
    --&gt;
                        
    <inertial>
      <mass value="0.7477"/>
      <origin xyz="0 -0.002 -0.0605"/>
      <inertia ixx="0.00152031725204" ixy="0" ixz="0" iyy="0.00152031725204" iyz="0" izz="0.00059816"/>
    </inertial>
  </link>
  <joint name="kinova_joint_1" type="revolute">
    <parent link="kinova_link_base"/>
    <child link="kinova_link_1"/>
    <axis xyz="0 0 1"/>
    <limit effort="30.5" lower="-62.8318530718" upper="62.8318530718" velocity="15"/>
    <!-- limit effort also defines torque limit and freeze controller gains -->
    <origin rpy="0 3.14159265359 0" xyz="0 0 0.15675"/>
    <dynamics damping="0.0" friction="0.0"/>
  </joint>
  <!--
   <xacro:unless value="${fixed}">
     <transmission name="${joint_name}_trans">
        <type>transmission_interface/SimpleTransmission</type>
        <joint name="${joint_name}">
          <hardwareInterface>EffortJointInterface</hardwareInterface>
        </joint>
        <actuator name="${joint_name}_actuator">
          <hardwareInterface>EffortJointInterface</hardwareInterface>
        <mechanicalReduction>160</mechanicalReduction>
        </actuator>
     </transmission>
     </xacro:unless>
-->
  <link name="kinova_link_2">
    <visual>
      <geometry>
        <mesh filename="package://kinova_description/meshes/arm.dae"/>
      </geometry>
      <material name="carbon_fiber">
        <color rgba="0.792156862745098 0.819607843137255 0.933333333333333 1"/>
      </material>
    </visual>
    <visual>
      <geometry>
        <mesh filename="package://kinova_description/meshes/ring_big.STL"/>
      </geometry>
    </visual>
    <collision>
      <geometry>
        <mesh filename="package://kinova_description/meshes/arm.dae"/>
      </geometry>
    </collision>
    --&gt;
                        
    <inertial>
      <mass value="0.99"/>
      <origin xyz="0 -0.2065 -0.01"/>
      <inertia ixx="0.010502207991" ixy="0" ixz="0" iyy="0.000792" iyz="0" izz="0.010502207991"/>
    </inertial>
  </link>
  <joint name="kinova_joint_2" type="revolute">
    <parent link="kinova_link_1"/>
    <child link="kinova_link_2"/>
    <axis xyz="0 0 1"/>
    <limit effort="30.5" lower="-62.8318530718" upper="62.8318530718" velocity="15"/>
    <!-- limit effort also defines torque limit and freeze controller gains -->
    <origin rpy="-1.57079632679 0 3.14159265359" xyz="0 0.0016 -0.11875"/>
    <dynamics damping="0.0" friction="0.0"/>
  </joint>
  <!--
   <xacro:unless value="${fixed}">
     <transmission name="${joint_name}_trans">
        <type>transmission_interface/SimpleTransmission</type>
        <joint name="${joint_name}">
          <hardwareInterface>EffortJointInterface</hardwareInterface>
        </joint>
        <actuator name="${joint_name}_actuator">
          <hardwareInterface>EffortJointInterface</hardwareInterface>
        <mechanicalReduction>160</mechanicalReduction>
        </actuator>
     </transmission>
     </xacro:unless>
-->
  <link name="kinova_link_3">
    <visual>
      <geometry>
        <mesh filename="package://kinova_description/meshes/forearm.dae"/>
      </geometry>
      <material name="carbon_fiber">
        <color rgba="0.792156862745098 0.819607843137255 0.933333333333333 1"/>
      </material>
    </visual>
    <visual>
      <geometry>
        <mesh filename="package://kinova_description/meshes/ring_big.STL"/>
      </geometry>
    </visual>
    <collision>
      <geometry>
        <mesh filename="package://kinova_description/meshes/forearm.dae"/>
      </geometry>
    </collision>
    --&gt;
                        
    <inertial>
      <mass value="0.6763"/>
      <origin xyz="0 0.081 -0.0086"/>
      <inertia ixx="0.00142022431908" ixy="0" ixz="0" iyy="0.000304335" iyz="0" izz="0.00142022431908"/>
    </inertial>
  </link>
  <joint name="kinova_joint_3" type="revolute">
    <parent link="kinova_link_2"/>
    <child link="kinova_link_3"/>
    <axis xyz="0 0 1"/>
    <limit effort="30.5" lower="-62.8318530718" upper="62.8318530718" velocity="15"/>
    <!-- limit effort also defines torque limit and freeze controller gains -->
    <origin rpy="0 3.14159265359 0" xyz="0 -0.410 0"/>
    <dynamics damping="0.0" friction="0.0"/>
  </joint>
  <!--
   <xacro:unless value="${fixed}">
     <transmission name="${joint_name}_trans">
        <type>transmission_interface/SimpleTransmission</type>
        <joint name="${joint_name}">
          <hardwareInterface>EffortJointInterface</hardwareInterface>
        </joint>
        <actuator name="${joint_name}_actuator">
          <hardwareInterface>EffortJointInterface</hardwareInterface>
        <mechanicalReduction>160</mechanicalReduction>
        </actuator>
     </transmission>
     </xacro:unless>
-->
  <link name="kinova_link_4">
    <visual>
      <geometry>
        <mesh filename="package://kinova_description/meshes/wrist_spherical_1.dae"/>
      </geometry>
      <material name="carbon_fiber">
        <color rgba="0.792156862745098 0.819607843137255 0.933333333333333 1"/>
      </material>
    </visual>
    <visual>
      <geometry>
        <mesh filename="package://kinova_description/meshes/ring_small.STL"/>
      </geometry>
    </visual>
    <collision>
      <geometry>
        <mesh filename="package://kinova_description/meshes/wrist_spherical_1.dae"/>
      </geometry>
    </collision>
    --&gt;
                        
    <inertial>
      <mass value="0.463"/>
      <origin xyz="0 0.0028848942 -0.0541932613"/>
      <inertia ixx="0.0004321316048" ixy="0" ixz="0" iyy="0.0004321316048" iyz="0" izz="9.26e-05"/>
    </inertial>
  </link>
  <joint name="kinova_joint_4" type="revolute">
    <parent link="kinova_link_3"/>
    <child link="kinova_link_4"/>
    <axis xyz="0 0 1"/>
    <limit effort="6.8" lower="-62.8318530718" upper="6.28318530718" velocity="15"/>
    <!-- limit effort also defines torque limit and freeze controller gains -->
    <origin rpy="-1.57079632679 0 3.14159265359" xyz="0 0.2073 -0.0114"/>
    <dynamics damping="0.0" friction="0.0"/>
  </joint>
  <!--
   <xacro:unless value="${fixed}">
     <transmission name="${joint_name}_trans">
        <type>transmission_interface/SimpleTransmission</type>
        <joint name="${joint_name}">
          <hardwareInterface>EffortJointInterface</hardwareInterface>
        </joint>
        <actuator name="${joint_name}_actuator">
          <hardwareInterface>EffortJointInterface</hardwareInterface>
        <mechanicalReduction>160</mechanicalReduction>
        </actuator>
     </transmission>
     </xacro:unless>
-->
  <link name="kinova_link_5">
    <visual>
      <geometry>
        <mesh filename="package://kinova_description/meshes/wrist_spherical_2.dae"/>
      </geometry>
      <material name="carbon_fiber">
        <color rgba="0.792156862745098 0.819607843137255 0.933333333333333 1"/>
      </material>
    </visual>
    <visual>
      <geometry>
        <mesh filename="package://kinova_description/meshes/ring_small.STL"/>
      </geometry>
    </visual>
    <collision>
      <geometry>
        <mesh filename="package://kinova_description/meshes/wrist_spherical_2.dae"/>
      </geometry>
    </collision>
    --&gt;
                        
    <inertial>
      <mass value="0.463"/>
      <origin xyz="0 0.0497208855 -0.0028562765"/>
      <inertia ixx="0.0004321316048" ixy="0" ixz="0" iyy="9.26e-05" iyz="0" izz="0.0004321316048"/>
    </inertial>
  </link>
  <joint name="kinova_joint_5" type="revolute">
    <parent link="kinova_link_4"/>
    <child link="kinova_link_5"/>
    <axis xyz="0 0 1"/>
    <limit effort="6.8" lower="-6.28318530718" upper="62.8318530718" velocity="15"/>
    <!-- limit effort also defines torque limit and freeze controller gains -->
    <origin rpy="1.57079632679 0 3.14159265359" xyz="0 0 -0.10375"/>
    <dynamics damping="0.0" friction="0.0"/>
  </joint>
  <!--
   <xacro:unless value="${fixed}">
     <transmission name="${joint_name}_trans">
        <type>transmission_interface/SimpleTransmission</type>
        <joint name="${joint_name}">
          <hardwareInterface>EffortJointInterface</hardwareInterface>
        </joint>
        <actuator name="${joint_name}_actuator">
          <hardwareInterface>EffortJointInterface</hardwareInterface>
        <mechanicalReduction>160</mechanicalReduction>
        </actuator>
     </transmission>
     </xacro:unless>
-->
  <link name="kinova_link_6">
    <visual>
      <geometry>
        <mesh filename="package://kinova_description/meshes/hand_3finger.dae"/>
      </geometry>
      <material name="carbon_fiber">
        <color rgba="0.792156862745098 0.819607843137255 0.933333333333333 1"/>
      </material>
    </visual>
    <visual>
      <geometry>
        <mesh filename="package://kinova_description/meshes/ring_small.STL"/>
      </geometry>
    </visual>
    <collision>
      <geometry>
        <mesh filename="package://kinova_description/meshes/hand_3finger.dae"/>
      </geometry>
    </collision>
    --&gt;
                        
    <inertial>
      <mass value="0.927"/>
      <origin xyz="0 0 -0.06"/>
      <inertia ixx="0.0004403232387" ixy="0" ixz="0" iyy="0.0004403232387" iyz="0" izz="0.0007416"/>
    </inertial>
  </link>
  <joint name="kinova_joint_6" type="revolute">
    <parent link="kinova_link_5"/>
    <child link="kinova_link_6"/>
    <axis xyz="0 0 1"/>
    <limit effort="6.8" lower="-62.8318530718" upper="62.8318530718" velocity="15"/>
    <!-- limit effort also defines torque limit and freeze controller gains -->
    <origin rpy="-1.57079632679 0 3.14159265359" xyz="0 0.10375 0"/>
    <dynamics damping="0.0" friction="0.0"/>
  </joint>
  <!--
   <xacro:unless value="${fixed}">
     <transmission name="${joint_name}_trans">
        <type>transmission_interface/SimpleTransmission</type>
        <joint name="${joint_name}">
          <hardwareInterface>EffortJointInterface</hardwareInterface>
        </joint>
        <actuator name="${joint_name}_actuator">
          <hardwareInterface>EffortJointInterface</hardwareInterface>
        <mechanicalReduction>160</mechanicalReduction>
        </actuator>
     </transmission>
     </xacro:unless>
-->
  <link name="kinova_end_effector">
    <!-- Inertial properties and a fixed revolute joint have been added to this link to make it possible to use the gazebo_link_attacher plugin -->
    <!-- Minor collision properties are added to avoid bug/crash when running model in Gazebo -->
    <visual>
      <geometry>
        <box size="0.0001 0.0001 0.0001"/>
      </geometry>
    </visual>
    <collision>
      <origin rpy="0.0 0.0 0.0" xyz="0.0 0.0 -0.1"/>
      <geometry>
        <box size="0.00001 0.00001 0.00001"/>
      </geometry>
    </collision>
    <inertial>
      <origin rpy="0 0 0" xyz="0.0 0.0 0.0"/>
      <mass value="0.01"/>
      <inertia ixx="0.01" ixy="0" ixz="0" iyy="0.01" iyz="0" izz="0.01"/>
    </inertial>
  </link>
  <joint name="kinova_joint_end_effector" type="fixed">
    <!--joint name="${joint_name}" type="fixed"-->
    <parent link="kinova_link_6"/>
    <child link="kinova_end_effector"/>
    <axis xyz="0 0 0"/>
    <limit effort="2000" lower="0" upper="0" velocity="1"/>
    <origin rpy="3.14159265359 0 0" xyz="0 0 -0.1600"/>
  </joint>
  <link name="kinova_link_finger_1">
    <visual>
      <geometry>
        <mesh filename="package://kinova_description/meshes/finger_proximal.dae"/>
      </geometry>
      <material name="carbon_fiber">
        <color rgba="0.792156862745098 0.819607843137255 0.933333333333333 1"/>
      </material>
    </visual>
    <collision>
      <geometry>
        <mesh filename="package://kinova_description/meshes/finger_proximal.dae"/>
      </geometry>
    </collision>
    --&gt;
                        
    <inertial>
      <mass value="0.01"/>
      <origin xyz="0.022 0 0"/>
      <inertia ixx="7.8999684e-07" ixy="0" ixz="0" iyy="7.8999684e-07" iyz="0" izz="8e-08"/>
    </inertial>
  </link>
  <joint name="kinova_joint_finger_1" type="revolute">
    <!-- originally revolute, but is set to fixed because hand is not being used yet -->
    <parent link="kinova_link_6"/>
    <child link="kinova_link_finger_1"/>
    <axis xyz="0 0 1"/>
    <origin rpy="-1.570796327 .649262481663582 1.35961148639407" xyz="0.00279 0.03126 -0.11467"/>
    <limit effort="2000" lower="0" upper="2" velocity="1"/>
  </joint>
  <!--
            <transmission name="${prefix}joint_finger_${finger_number}_trans">
                    <type>transmission_interface/SimpleTransmission</type>
                    <joint name="${prefix}joint_finger_${finger_number}">
                      <hardwareInterface>EffortJointInterface</hardwareInterface>
                    </joint>
                    <actuator name="${prefix}joint_finger_${finger_number}_actuator">
                    <hardwareInterface>EffortJointInterface</hardwareInterface>
                    <mechanicalReduction>1</mechanicalReduction>
                    </actuator>
            </transmission>
-->
  <link name="kinova_link_finger_tip_1">
    <visual>
      <geometry>
        <mesh filename="package://kinova_description/meshes/finger_distal.dae"/>
      </geometry>
      <material name="carbon_fiber">
        <color rgba="0.792156862745098 0.819607843137255 0.933333333333333 1"/>
      </material>
    </visual>
    <collision>
      <geometry>
        <mesh filename="package://kinova_description/meshes/finger_distal.dae"/>
      </geometry>
    </collision>
    --&gt;
                        
    <inertial>
      <mass value="0.01"/>
      <origin xyz="0.022 0 0"/>
      <inertia ixx="7.8999684e-07" ixy="0" ixz="0" iyy="7.8999684e-07" iyz="0" izz="8e-08"/>
    </inertial>
  </link>
  <joint name="kinova_joint_finger_tip_1" type="fixed">
    <parent link="kinova_link_finger_1"/>
    <child link="kinova_link_finger_tip_1"/>
    <axis xyz="0 0 1"/>
    <origin rpy="0 0 0" xyz="0.044 -0.003 0"/>
    <limit effort="2000" lower="0" upper="2" velocity="1"/>
  </joint>
  <link name="kinova_link_finger_2">
    <visual>
      <geometry>
        <mesh filename="package://kinova_description/meshes/finger_proximal.dae"/>
      </geometry>
      <material name="carbon_fiber">
        <color rgba="0.792156862745098 0.819607843137255 0.933333333333333 1"/>
      </material>
    </visual>
    <collision>
      <geometry>
        <mesh filename="package://kinova_description/meshes/finger_proximal.dae"/>
      </geometry>
    </collision>
    --&gt;
                        
    <inertial>
      <mass value="0.01"/>
      <origin xyz="0.022 0 0"/>
      <inertia ixx="7.8999684e-07" ixy="0" ixz="0" iyy="7.8999684e-07" iyz="0" izz="8e-08"/>
    </inertial>
  </link>
  <joint name="kinova_joint_finger_2" type="revolute">
    <!-- originally revolute, but is set to fixed because hand is not being used yet -->
    <parent link="kinova_link_6"/>
    <child link="kinova_link_finger_2"/>
    <axis xyz="0 0 1"/>
    <origin rpy="-1.570796327 .649262481663582 -1.38614049188413" xyz="0.02226 -0.02707 -0.11482"/>
    <limit effort="2000" lower="0" upper="2" velocity="1"/>
  </joint>
  <!--
            <transmission name="${prefix}joint_finger_${finger_number}_trans">
                    <type>transmission_interface/SimpleTransmission</type>
                    <joint name="${prefix}joint_finger_${finger_number}">
                      <hardwareInterface>EffortJointInterface</hardwareInterface>
                    </joint>
                    <actuator name="${prefix}joint_finger_${finger_number}_actuator">
                    <hardwareInterface>EffortJointInterface</hardwareInterface>
                    <mechanicalReduction>1</mechanicalReduction>
                    </actuator>
            </transmission>
-->
  <link name="kinova_link_finger_tip_2">
    <visual>
      <geometry>
        <mesh filename="package://kinova_description/meshes/finger_distal.dae"/>
      </geometry>
      <material name="carbon_fiber">
        <color rgba="0.792156862745098 0.819607843137255 0.933333333333333 1"/>
      </material>
    </visual>
    <collision>
      <geometry>
        <mesh filename="package://kinova_description/meshes/finger_distal.dae"/>
      </geometry>
    </collision>
    --&gt;
                        
    <inertial>
      <mass value="0.01"/>
      <origin xyz="0.022 0 0"/>
      <inertia ixx="7.8999684e-07" ixy="0" ixz="0" iyy="7.8999684e-07" iyz="0" izz="8e-08"/>
    </inertial>
  </link>
  <joint name="kinova_joint_finger_tip_2" type="fixed">
    <parent link="kinova_link_finger_2"/>
    <child link="kinova_link_finger_tip_2"/>
    <axis xyz="0 0 1"/>
    <origin rpy="0 0 0" xyz="0.044 -0.003 0"/>
    <limit effort="2000" lower="0" upper="2" velocity="1"/>
  </joint>
  <link name="kinova_link_finger_3">
    <visual>
      <geometry>
        <mesh filename="package://kinova_description/meshes/finger_proximal.dae"/>
      </geometry>
      <material name="carbon_fiber">
        <color rgba="0.792156862745098 0.819607843137255 0.933333333333333 1"/>
      </material>
    </visual>
    <collision>
      <geometry>
        <mesh filename="package://kinova_description/meshes/finger_proximal.dae"/>
      </geometry>
    </collision>
    --&gt;
                        
    <inertial>
      <mass value="0.01"/>
      <origin xyz="0.022 0 0"/>
      <inertia ixx="7.8999684e-07" ixy="0" ixz="0" iyy="7.8999684e-07" iyz="0" izz="8e-08"/>
    </inertial>
  </link>
  <joint name="kinova_joint_finger_3" type="revolute">
    <!-- originally revolute, but is set to fixed because hand is not being used yet -->
    <parent link="kinova_link_6"/>
    <child link="kinova_link_finger_3"/>
    <axis xyz="0 0 1"/>
    <origin rpy="-1.570796327 .649262481663582 -1.75545216211587" xyz="-0.02226 -0.02707 -0.11482"/>
    <limit effort="2000" lower="0" upper="2" velocity="1"/>
  </joint>
  <!--
            <transmission name="${prefix}joint_finger_${finger_number}_trans">
                    <type>transmission_interface/SimpleTransmission</type>
                    <joint name="${prefix}joint_finger_${finger_number}">
                      <hardwareInterface>EffortJointInterface</hardwareInterface>
                    </joint>
                    <actuator name="${prefix}joint_finger_${finger_number}_actuator">
                    <hardwareInterface>EffortJointInterface</hardwareInterface>
                    <mechanicalReduction>1</mechanicalReduction>
                    </actuator>
            </transmission>
-->
  <link name="kinova_link_finger_tip_3">
    <visual>
      <geometry>
        <mesh filename="package://kinova_description/meshes/finger_distal.dae"/>
      </geometry>
      <material name="carbon_fiber">
        <color rgba="0.792156862745098 0.819607843137255 0.933333333333333 1"/>
      </material>
    </visual>
    <collision>
      <geometry>
        <mesh filename="package://kinova_description/meshes/finger_distal.dae"/>
      </geometry>
    </collision>
    --&gt;
                        
    <inertial>
      <mass value="0.01"/>
      <origin xyz="0.022 0 0"/>
      <inertia ixx="7.8999684e-07" ixy="0" ixz="0" iyy="7.8999684e-07" iyz="0" izz="8e-08"/>
    </inertial>
  </link>
  <joint name="kinova_joint_finger_tip_3" type="fixed">
    <parent link="kinova_link_finger_3"/>
    <child link="kinova_link_finger_tip_3"/>
    <axis xyz="0 0 1"/>
    <origin rpy="0 0 0" xyz="0.044 -0.003 0"/>
    <limit effort="2000" lower="0" upper="2" velocity="1"/>
  </joint>
</robot>

